{
    "results": [
        {
            "type": "kics",
            "id": "2PDODqBcKYTHIUn6t/DCCEWU2Rs=",
            "similarityId": "da389e44a3558dd8333780ca45f1f08f89be2933d15f6ea86b207f5b0ace0ba8",
            "status": "RECURRENT",
            "state": "TO_VERIFY",
            "severity": "INFO",
            "confidenceLevel": 0,
            "created": "2024-11-14T03:53:06Z",
            "firstFoundAt": "2024-11-12T12:42:13Z",
            "foundAt": "2024-11-14T03:53:06Z",
            "firstScanId": "ffb57bf8-3538-4457-a5d7-90ffb2ce06bd",
            "description": "Volumes shared between containers can cause data corruption or can be used to share malicious files between containers.",
            "data": {
                "queryId": "8c978947-0ff6-485c-b0c2-0bfca6026466",
                "queryName": "Shared Volumes Between Containers",
                "group": "Insecure Configurations [Taken from category]",
                "queryUrl": "Shared Volumes Between Containers [Taken from query_name]",
                "queryId": "8c978947-0ff6-485c-b0c2-0bfca6026466 [Taken from query_id]",
                "fileName": "/docker-compose.yml",
                "line": 19,
                "platform": "DockerCompose",
                "issueType": "IncorrectValue",
                "expectedValue": "There shouldn't be volumes shared between containers",
                "value": "Volume .:/app shared between containers"
            },
            "comments": {},
            "vulnerabilityDetails": {}
        },
        {
            "type": "kics",
            "id": "bCFPgwoeP9tPUgt5klPVIxRJnJg=",
            "similarityId": "86b8013efaa2081029a720b917349bd771ecd733bcd166f561da48db7c81f991",
            "status": "RECURRENT",
            "state": "TO_VERIFY",
            "severity": "INFO",
            "confidenceLevel": 0,
            "created": "2024-11-14T03:53:06Z",
            "firstFoundAt": "2024-11-12T12:42:13Z",
            "foundAt": "2024-11-14T03:53:06Z",
            "firstScanId": "ffb57bf8-3538-4457-a5d7-90ffb2ce06bd",
            "description": "Volumes shared between containers can cause data corruption or can be used to share malicious files between containers.",
            "data": {
                "queryId": "8c978947-0ff6-485c-b0c2-0bfca6026466",
                "queryName": "Shared Volumes Between Containers",
                "group": "Insecure Configurations [Taken from category]",
                "queryUrl": "Shared Volumes Between Containers [Taken from query_name]",
                "queryId": "8c978947-0ff6-485c-b0c2-0bfca6026466 [Taken from query_id]",
                "fileName": "/pygoat/docker-compose.yml",
                "line": 18,
                "platform": "DockerCompose",
                "issueType": "IncorrectValue",
                "expectedValue": "There shouldn't be volumes shared between containers",
                "value": "Volume .:/code shared between containers"
            },
            "comments": {},
            "vulnerabilityDetails": {}
        },
        {
            "type": "kics",
            "id": "c40gj7VosEaMFOIYBAEJQjpGTnw=",
            "similarityId": "6c566ebf6d6520cc35499eb1ad647c76529b2dd3bae3819b85407607ca15cf03",
            "status": "RECURRENT",
            "state": "TO_VERIFY",
            "severity": "INFO",
            "confidenceLevel": 0,
            "created": "2024-11-14T03:53:06Z",
            "firstFoundAt": "2024-11-12T12:42:13Z",
            "foundAt": "2024-11-14T03:53:06Z",
            "firstScanId": "ffb57bf8-3538-4457-a5d7-90ffb2ce06bd",
            "description": "Volumes shared between containers can cause data corruption or can be used to share malicious files between containers.",
            "data": {
                "queryId": "8c978947-0ff6-485c-b0c2-0bfca6026466",
                "queryName": "Shared Volumes Between Containers",
                "group": "Insecure Configurations [Taken from category]",
                "queryUrl": "Shared Volumes Between Containers [Taken from query_name]",
                "queryId": "8c978947-0ff6-485c-b0c2-0bfca6026466 [Taken from query_id]",
                "fileName": "/pygoat/docker-compose.yml",
                "line": 10,
                "platform": "DockerCompose",
                "issueType": "IncorrectValue",
                "expectedValue": "There shouldn't be volumes shared between containers",
                "value": "Volume .:/code shared between containers"
            },
            "comments": {},
            "vulnerabilityDetails": {}
        },
        {
            "type": "containers",
            "id": "CVE-2020-36782",
            "similarityId": "CVE-2020-36782",
            "status": "RECURRENT",
            "state": "TO_VERIFY",
            "severity": "INFO",
            "confidenceLevel": 0,
            "created": "2024-11-14T03:52:50Z",
            "firstFoundAt": "2024-11-12T12:44:08Z",
            "foundAt": "2024-11-14T03:52:50Z",
            "firstScanId": "ffb57bf8-3538-4457-a5d7-90ffb2ce06bd",
            "description": "In the Linux kernel, the following vulnerability has been resolved:\n\ni2c: imx-lpi2c: fix reference leak when pm_runtime_get_sync fails\n\nThe PM reference count is not expected to be incremented on\nreturn in lpi2c_imx_master_enable.\n\nHowever, pm_runtime_get_sync will increment the PM reference\ncount even failed. Forgetting to putting operation will result\nin a reference leak here.\n\nReplace it with pm_runtime_resume_and_get to keep usage\ncounter balanced.",
            "data": {
                "packageName": "linux",
                "packageVersion": "4.19.67-2+deb10u2",
                "imageName": "library/python",
                "imageTag": "3.7.5-buster",
                "imageFilePath": "pygoat/Dockerfile",
                "imageOrigin": "Dockerfile"
            },
            "comments": {
                "comments": ""
            },
            "vulnerabilityDetails": {
                "cvssScore": 0,
                "cveName": "CVE-2020-36782",
                "cweId": "",
                "cvss": null
            }
        },
        {
            "type": "containers",
            "id": "CVE-2020-36782",
            "similarityId": "CVE-2020-36782",
            "status": "RECURRENT",
            "state": "TO_VERIFY",
            "severity": "INFO",
            "confidenceLevel": 0,
            "created": "2024-11-14T03:52:50Z",
            "firstFoundAt": "2024-11-12T12:44:08Z",
            "foundAt": "2024-11-14T03:52:50Z",
            "firstScanId": "ffb57bf8-3538-4457-a5d7-90ffb2ce06bd",
            "description": "In the Linux kernel, the following vulnerability has been resolved:\n\ni2c: imx-lpi2c: fix reference leak when pm_runtime_get_sync fails\n\nThe PM reference count is not expected to be incremented on\nreturn in lpi2c_imx_master_enable.\n\nHowever, pm_runtime_get_sync will increment the PM reference\ncount even failed. Forgetting to putting operation will result\nin a reference leak here.\n\nReplace it with pm_runtime_resume_and_get to keep usage\ncounter balanced.",
            "data": {
                "packageName": "linux-libc-dev",
                "packageVersion": "4.19.67-2+deb10u2",
                "imageName": "library/python",
                "imageTag": "3.7.5-buster",
                "imageFilePath": "pygoat/Dockerfile",
                "imageOrigin": "Dockerfile"
            },
            "comments": {
                "comments": ""
            },
            "vulnerabilityDetails": {
                "cvssScore": 0,
                "cveName": "CVE-2020-36782",
                "cweId": "",
                "cvss": null
            }
        },
        {
            "type": "containers",
            "id": "CVE-2020-36783",
            "similarityId": "CVE-2020-36783",
            "status": "RECURRENT",
            "state": "TO_VERIFY",
            "severity": "INFO",
            "confidenceLevel": 0,
            "created": "2024-11-14T03:52:50Z",
            "firstFoundAt": "2024-11-12T12:44:08Z",
            "foundAt": "2024-11-14T03:52:50Z",
            "firstScanId": "ffb57bf8-3538-4457-a5d7-90ffb2ce06bd",
            "description": "In the Linux kernel, the following vulnerability has been resolved:\n\ni2c: img-scb: fix reference leak when pm_runtime_get_sync fails\n\nThe PM reference count is not expected to be incremented on\nreturn in functions img_i2c_xfer and img_i2c_init.\n\nHowever, pm_runtime_get_sync will increment the PM reference\ncount even failed. Forgetting to putting operation will result\nin a reference leak here.\n\nReplace it with pm_runtime_resume_and_get to keep usage\ncounter balanced.",
            "data": {
                "packageName": "linux",
                "packageVersion": "4.19.67-2+deb10u2",
                "imageName": "library/python",
                "imageTag": "3.7.5-buster",
                "imageFilePath": "pygoat/Dockerfile",
                "imageOrigin": "Dockerfile"
            },
            "comments": {
                "comments": ""
            },
            "vulnerabilityDetails": {
                "cvssScore": 0,
                "cveName": "CVE-2020-36783",
                "cweId": "",
                "cvss": null
            }
        },
        {
            "type": "containers",
            "id": "CVE-2020-36783",
            "similarityId": "CVE-2020-36783",
            "status": "RECURRENT",
            "state": "TO_VERIFY",
            "severity": "INFO",
            "confidenceLevel": 0,
            "created": "2024-11-14T03:52:50Z",
            "firstFoundAt": "2024-11-12T12:44:08Z",
            "foundAt": "2024-11-14T03:52:50Z",
            "firstScanId": "ffb57bf8-3538-4457-a5d7-90ffb2ce06bd",
            "description": "In the Linux kernel, the following vulnerability has been resolved:\n\ni2c: img-scb: fix reference leak when pm_runtime_get_sync fails\n\nThe PM reference count is not expected to be incremented on\nreturn in functions img_i2c_xfer and img_i2c_init.\n\nHowever, pm_runtime_get_sync will increment the PM reference\ncount even failed. Forgetting to putting operation will result\nin a reference leak here.\n\nReplace it with pm_runtime_resume_and_get to keep usage\ncounter balanced.",
            "data": {
                "packageName": "linux-libc-dev",
                "packageVersion": "4.19.67-2+deb10u2",
                "imageName": "library/python",
                "imageTag": "3.7.5-buster",
                "imageFilePath": "pygoat/Dockerfile",
                "imageOrigin": "Dockerfile"
            },
            "comments": {
                "comments": ""
            },
            "vulnerabilityDetails": {
                "cvssScore": 0,
                "cveName": "CVE-2020-36783",
                "cweId": "",
                "cvss": null
            }
        },
        {
            "type": "containers",
            "id": "CVE-2020-36784",
            "similarityId": "CVE-2020-36784",
            "status": "RECURRENT",
            "state": "TO_VERIFY",
            "severity": "INFO",
            "confidenceLevel": 0,
            "created": "2024-11-14T03:52:50Z",
            "firstFoundAt": "2024-11-12T12:44:08Z",
            "foundAt": "2024-11-14T03:52:50Z",
            "firstScanId": "ffb57bf8-3538-4457-a5d7-90ffb2ce06bd",
            "description": "In the Linux kernel, the following vulnerability has been resolved:\n\ni2c: cadence: fix reference leak when pm_runtime_get_sync fails\n\nThe PM reference count is not expected to be incremented on\nreturn in functions cdns_i2c_master_xfer and cdns_reg_slave.\n\nHowever, pm_runtime_get_sync will increment pm usage counter\neven failed. Forgetting to putting operation will result in a\nreference leak here.\n\nReplace it with pm_runtime_resume_and_get to keep usage\ncounter balanced.",
            "data": {
                "packageName": "linux",
                "packageVersion": "4.19.67-2+deb10u2",
                "imageName": "library/python",
                "imageTag": "3.7.5-buster",
                "imageFilePath": "pygoat/Dockerfile",
                "imageOrigin": "Dockerfile"
            },
            "comments": {
                "comments": ""
            },
            "vulnerabilityDetails": {
                "cvssScore": 0,
                "cveName": "CVE-2020-36784",
                "cweId": "",
                "cvss": null
            }
        },
        {
            "type": "containers",
            "id": "CVE-2020-36784",
            "similarityId": "CVE-2020-36784",
            "status": "RECURRENT",
            "state": "TO_VERIFY",
            "severity": "INFO",
            "confidenceLevel": 0,
            "created": "2024-11-14T03:52:50Z",
            "firstFoundAt": "2024-11-12T12:44:08Z",
            "foundAt": "2024-11-14T03:52:50Z",
            "firstScanId": "ffb57bf8-3538-4457-a5d7-90ffb2ce06bd",
            "description": "In the Linux kernel, the following vulnerability has been resolved:\n\ni2c: cadence: fix reference leak when pm_runtime_get_sync fails\n\nThe PM reference count is not expected to be incremented on\nreturn in functions cdns_i2c_master_xfer and cdns_reg_slave.\n\nHowever, pm_runtime_get_sync will increment pm usage counter\neven failed. Forgetting to putting operation will result in a\nreference leak here.\n\nReplace it with pm_runtime_resume_and_get to keep usage\ncounter balanced.",
            "data": {
                "packageName": "linux-libc-dev",
                "packageVersion": "4.19.67-2+deb10u2",
                "imageName": "library/python",
                "imageTag": "3.7.5-buster",
                "imageFilePath": "pygoat/Dockerfile",
                "imageOrigin": "Dockerfile"
            },
            "comments": {
                "comments": ""
            },
            "vulnerabilityDetails": {
                "cvssScore": 0,
                "cveName": "CVE-2020-36784",
                "cweId": "",
                "cvss": null
            }
        },
        {
            "type": "containers",
            "id": "CVE-2021-3487",
            "similarityId": "CVE-2021-3487",
            "status": "RECURRENT",
            "state": "TO_VERIFY",
            "severity": "INFO",
            "confidenceLevel": 0,
            "created": "2024-11-14T03:52:50Z",
            "firstFoundAt": "2024-11-12T12:44:08Z",
            "foundAt": "2024-11-14T03:52:50Z",
            "firstScanId": "ffb57bf8-3538-4457-a5d7-90ffb2ce06bd",
            "description": "Rejected reason: Non Security Issue. See the binutils security policy for more details, https://sourceware.org/cgit/binutils-gdb/tree/binutils/SECURITY.txt",
            "data": {
                "packageName": "libbinutils",
                "packageVersion": "2.31.1-16",
                "imageName": "library/python",
                "imageTag": "3.7.5-buster",
                "imageFilePath": "pygoat/Dockerfile",
                "imageOrigin": "Dockerfile"
            },
            "comments": {
                "comments": ""
            },
            "vulnerabilityDetails": {
                "cvssScore": 0,
                "cveName": "CVE-2021-3487",
                "cweId": "",
                "cvss": null
            }
        },
        {
            "type": "containers",
            "id": "CVE-2021-3487",
            "similarityId": "CVE-2021-3487",
            "status": "RECURRENT",
            "state": "TO_VERIFY",
            "severity": "INFO",
            "confidenceLevel": 0,
            "created": "2024-11-14T03:52:50Z",
            "firstFoundAt": "2024-11-12T12:44:08Z",
            "foundAt": "2024-11-14T03:52:50Z",
            "firstScanId": "ffb57bf8-3538-4457-a5d7-90ffb2ce06bd",
            "description": "Rejected reason: Non Security Issue. See the binutils security policy for more details, https://sourceware.org/cgit/binutils-gdb/tree/binutils/SECURITY.txt",
            "data": {
                "packageName": "binutils-common",
                "packageVersion": "2.31.1-16",
                "imageName": "library/python",
                "imageTag": "3.7.5-buster",
                "imageFilePath": "pygoat/Dockerfile",
                "imageOrigin": "Dockerfile"
            },
            "comments": {
                "comments": ""
            },
            "vulnerabilityDetails": {
                "cvssScore": 0,
                "cveName": "CVE-2021-3487",
                "cweId": "",
                "cvss": null
            }
        },
        {
            "type": "containers",
            "id": "CVE-2021-3487",
            "similarityId": "CVE-2021-3487",
            "status": "RECURRENT",
            "state": "TO_VERIFY",
            "severity": "INFO",
            "confidenceLevel": 0,
            "created": "2024-11-14T03:52:50Z",
            "firstFoundAt": "2024-11-12T12:44:08Z",
            "foundAt": "2024-11-14T03:52:50Z",
            "firstScanId": "ffb57bf8-3538-4457-a5d7-90ffb2ce06bd",
            "description": "Rejected reason: Non Security Issue. See the binutils security policy for more details, https://sourceware.org/cgit/binutils-gdb/tree/binutils/SECURITY.txt",
            "data": {
                "packageName": "binutils",
                "packageVersion": "2.31.1-16",
                "imageName": "library/python",
                "imageTag": "3.7.5-buster",
                "imageFilePath": "pygoat/Dockerfile",
                "imageOrigin": "Dockerfile"
            },
            "comments": {
                "comments": ""
            },
            "vulnerabilityDetails": {
                "cvssScore": 0,
                "cveName": "CVE-2021-3487",
                "cweId": "",
                "cvss": null
            }
        },
        {
            "type": "containers",
            "id": "CVE-2021-46955",
            "similarityId": "CVE-2021-46955",
            "status": "RECURRENT",
            "state": "TO_VERIFY",
            "severity": "INFO",
            "confidenceLevel": 0,
            "created": "2024-11-14T03:52:50Z",
            "firstFoundAt": "2024-11-12T12:44:08Z",
            "foundAt": "2024-11-14T03:52:50Z",
            "firstScanId": "ffb57bf8-3538-4457-a5d7-90ffb2ce06bd",
            "description": "In the Linux kernel, the following vulnerability has been resolved:\n\nopenvswitch: fix stack OOB read while fragmenting IPv4 packets\n\nrunning openvswitch on kernels built with KASAN, it's possible to see the\nfollowing splat while testing fragmentation of IPv4 packets:\n\n BUG: KASAN: stack-out-of-bounds in ip_do_fragment+0x1b03/0x1f60\n Read of size 1 at addr ffff888112fc713c by task handler2/1367\n\n CPU: 0 PID: 1367 Comm: handler2 Not tainted 5.12.0-rc6+ #418\n Hardware name: Red Hat KVM, BIOS 1.11.1-4.module+el8.1.0+4066+0f1aadab 04/01/2014\n Call Trace:\n  dump_stack+0x92/0xc1\n  print_address_description.constprop.7+0x1a/0x150\n  kasan_report.cold.13+0x7f/0x111\n  ip_do_fragment+0x1b03/0x1f60\n  ovs_fragment+0x5bf/0x840 [openvswitch]\n  do_execute_actions+0x1bd5/0x2400 [openvswitch]\n  ovs_execute_actions+0xc8/0x3d0 [openvswitch]\n  ovs_packet_cmd_execute+0xa39/0x1150 [openvswitch]\n  genl_family_rcv_msg_doit.isra.15+0x227/0x2d0\n  genl_rcv_msg+0x287/0x490\n  netlink_rcv_skb+0x120/0x380\n  genl_rcv+0x24/0x40\n  netlink_unicast+0x439/0x630\n  netlink_sendmsg+0x719/0xbf0\n  sock_sendmsg+0xe2/0x110\n  ____sys_sendmsg+0x5ba/0x890\n  ___sys_sendmsg+0xe9/0x160\n  __sys_sendmsg+0xd3/0x170\n  do_syscall_64+0x33/0x40\n  entry_SYSCALL_64_after_hwframe+0x44/0xae\n RIP: 0033:0x7f957079db07\n Code: c3 66 90 41 54 41 89 d4 55 48 89 f5 53 89 fb 48 83 ec 10 e8 eb ec ff ff 44 89 e2 48 89 ee 89 df 41 89 c0 b8 2e 00 00 00 0f 05 <48> 3d 00 f0 ff ff 77 35 44 89 c7 48 89 44 24 08 e8 24 ed ff ff 48\n RSP: 002b:00007f956ce35a50 EFLAGS: 00000293 ORIG_RAX: 000000000000002e\n RAX: ffffffffffffffda RBX: 0000000000000019 RCX: 00007f957079db07\n RDX: 0000000000000000 RSI: 00007f956ce35ae0 RDI: 0000000000000019\n RBP: 00007f956ce35ae0 R08: 0000000000000000 R09: 00007f9558006730\n R10: 0000000000000000 R11: 0000000000000293 R12: 0000000000000000\n R13: 00007f956ce37308 R14: 00007f956ce35f80 R15: 00007f956ce35ae0\n\n The buggy address belongs to the page:\n page:00000000af2a1d93 refcount:0 mapcount:0 mapping:0000000000000000 index:0x0 pfn:0x112fc7\n flags: 0x17ffffc0000000()\n raw: 0017ffffc0000000 0000000000000000 dead000000000122 0000000000000000\n raw: 0000000000000000 0000000000000000 00000000ffffffff 0000000000000000\n page dumped because: kasan: bad access detected\n\n addr ffff888112fc713c is located in stack of task handler2/1367 at offset 180 in frame:\n  ovs_fragment+0x0/0x840 [openvswitch]\n\n this frame has 2 objects:\n  [32, 144) 'ovs_dst'\n  [192, 424) 'ovs_rt'\n\n Memory state around the buggy address:\n  ffff888112fc7000: f3 00 00 00 00 00 00 00 00 00 00 00 00 00 00 00\n  ffff888112fc7080: 00 f1 f1 f1 f1 00 00 00 00 00 00 00 00 00 00 00\n >ffff888112fc7100: 00 00 00 f2 f2 f2 f2 f2 f2 00 00 00 00 00 00 00\n                                         ^\n  ffff888112fc7180: 00 00 00 00 00 00 00 00 00 00 00 00 00 00 00 00\n  ffff888112fc7200: 00 00 00 00 00 00 f2 f2 f2 00 00 00 00 00 00 00\n\nfor IPv4 packets, ovs_fragment() uses a temporary struct dst_entry. Then,\nin the following call graph:\n\n  ip_do_fragment()\n    ip_skb_dst_mtu()\n      ip_dst_mtu_maybe_forward()\n        ip_mtu_locked()\n\nthe pointer to struct dst_entry is used as pointer to struct rtable: this\nturns the access to struct members like rt_mtu_locked into an OOB read in\nthe stack. Fix this changing the temporary variable used for IPv4 packets\nin ovs_fragment(), similarly to what is done for IPv6 few lines below.",
            "data": {
                "packageName": "linux-libc-dev",
                "packageVersion": "4.19.67-2+deb10u2",
                "imageName": "library/python",
                "imageTag": "3.7.5-buster",
                "imageFilePath": "pygoat/Dockerfile",
                "imageOrigin": "Dockerfile"
            },
            "comments": {
                "comments": ""
            },
            "vulnerabilityDetails": {
                "cvssScore": 0,
                "cveName": "CVE-2021-46955",
                "cweId": "",
                "cvss": null
            }
        },
        {
            "type": "containers",
            "id": "CVE-2021-46955",
            "similarityId": "CVE-2021-46955",
            "status": "RECURRENT",
            "state": "TO_VERIFY",
            "severity": "INFO",
            "confidenceLevel": 0,
            "created": "2024-11-14T03:52:50Z",
            "firstFoundAt": "2024-11-12T12:44:08Z",
            "foundAt": "2024-11-14T03:52:50Z",
            "firstScanId": "ffb57bf8-3538-4457-a5d7-90ffb2ce06bd",
            "description": "In the Linux kernel, the following vulnerability has been resolved:\n\nopenvswitch: fix stack OOB read while fragmenting IPv4 packets\n\nrunning openvswitch on kernels built with KASAN, it's possible to see the\nfollowing splat while testing fragmentation of IPv4 packets:\n\n BUG: KASAN: stack-out-of-bounds in ip_do_fragment+0x1b03/0x1f60\n Read of size 1 at addr ffff888112fc713c by task handler2/1367\n\n CPU: 0 PID: 1367 Comm: handler2 Not tainted 5.12.0-rc6+ #418\n Hardware name: Red Hat KVM, BIOS 1.11.1-4.module+el8.1.0+4066+0f1aadab 04/01/2014\n Call Trace:\n  dump_stack+0x92/0xc1\n  print_address_description.constprop.7+0x1a/0x150\n  kasan_report.cold.13+0x7f/0x111\n  ip_do_fragment+0x1b03/0x1f60\n  ovs_fragment+0x5bf/0x840 [openvswitch]\n  do_execute_actions+0x1bd5/0x2400 [openvswitch]\n  ovs_execute_actions+0xc8/0x3d0 [openvswitch]\n  ovs_packet_cmd_execute+0xa39/0x1150 [openvswitch]\n  genl_family_rcv_msg_doit.isra.15+0x227/0x2d0\n  genl_rcv_msg+0x287/0x490\n  netlink_rcv_skb+0x120/0x380\n  genl_rcv+0x24/0x40\n  netlink_unicast+0x439/0x630\n  netlink_sendmsg+0x719/0xbf0\n  sock_sendmsg+0xe2/0x110\n  ____sys_sendmsg+0x5ba/0x890\n  ___sys_sendmsg+0xe9/0x160\n  __sys_sendmsg+0xd3/0x170\n  do_syscall_64+0x33/0x40\n  entry_SYSCALL_64_after_hwframe+0x44/0xae\n RIP: 0033:0x7f957079db07\n Code: c3 66 90 41 54 41 89 d4 55 48 89 f5 53 89 fb 48 83 ec 10 e8 eb ec ff ff 44 89 e2 48 89 ee 89 df 41 89 c0 b8 2e 00 00 00 0f 05 <48> 3d 00 f0 ff ff 77 35 44 89 c7 48 89 44 24 08 e8 24 ed ff ff 48\n RSP: 002b:00007f956ce35a50 EFLAGS: 00000293 ORIG_RAX: 000000000000002e\n RAX: ffffffffffffffda RBX: 0000000000000019 RCX: 00007f957079db07\n RDX: 0000000000000000 RSI: 00007f956ce35ae0 RDI: 0000000000000019\n RBP: 00007f956ce35ae0 R08: 0000000000000000 R09: 00007f9558006730\n R10: 0000000000000000 R11: 0000000000000293 R12: 0000000000000000\n R13: 00007f956ce37308 R14: 00007f956ce35f80 R15: 00007f956ce35ae0\n\n The buggy address belongs to the page:\n page:00000000af2a1d93 refcount:0 mapcount:0 mapping:0000000000000000 index:0x0 pfn:0x112fc7\n flags: 0x17ffffc0000000()\n raw: 0017ffffc0000000 0000000000000000 dead000000000122 0000000000000000\n raw: 0000000000000000 0000000000000000 00000000ffffffff 0000000000000000\n page dumped because: kasan: bad access detected\n\n addr ffff888112fc713c is located in stack of task handler2/1367 at offset 180 in frame:\n  ovs_fragment+0x0/0x840 [openvswitch]\n\n this frame has 2 objects:\n  [32, 144) 'ovs_dst'\n  [192, 424) 'ovs_rt'\n\n Memory state around the buggy address:\n  ffff888112fc7000: f3 00 00 00 00 00 00 00 00 00 00 00 00 00 00 00\n  ffff888112fc7080: 00 f1 f1 f1 f1 00 00 00 00 00 00 00 00 00 00 00\n >ffff888112fc7100: 00 00 00 f2 f2 f2 f2 f2 f2 00 00 00 00 00 00 00\n                                         ^\n  ffff888112fc7180: 00 00 00 00 00 00 00 00 00 00 00 00 00 00 00 00\n  ffff888112fc7200: 00 00 00 00 00 00 f2 f2 f2 00 00 00 00 00 00 00\n\nfor IPv4 packets, ovs_fragment() uses a temporary struct dst_entry. Then,\nin the following call graph:\n\n  ip_do_fragment()\n    ip_skb_dst_mtu()\n      ip_dst_mtu_maybe_forward()\n        ip_mtu_locked()\n\nthe pointer to struct dst_entry is used as pointer to struct rtable: this\nturns the access to struct members like rt_mtu_locked into an OOB read in\nthe stack. Fix this changing the temporary variable used for IPv4 packets\nin ovs_fragment(), similarly to what is done for IPv6 few lines below.",
            "data": {
                "packageName": "linux",
                "packageVersion": "4.19.67-2+deb10u2",
                "imageName": "library/python",
                "imageTag": "3.7.5-buster",
                "imageFilePath": "pygoat/Dockerfile",
                "imageOrigin": "Dockerfile"
            },
            "comments": {
                "comments": ""
            },
            "vulnerabilityDetails": {
                "cvssScore": 0,
                "cveName": "CVE-2021-46955",
                "cweId": "",
                "cvss": null
            }
        },
        {
            "type": "containers",
            "id": "CVE-2021-46959",
            "similarityId": "CVE-2021-46959",
            "status": "RECURRENT",
            "state": "TO_VERIFY",
            "severity": "INFO",
            "confidenceLevel": 0,
            "created": "2024-11-14T03:52:50Z",
            "firstFoundAt": "2024-11-12T12:44:08Z",
            "foundAt": "2024-11-14T03:52:50Z",
            "firstScanId": "ffb57bf8-3538-4457-a5d7-90ffb2ce06bd",
            "description": "In the Linux kernel, the following vulnerability has been resolved:\n\nspi: Fix use-after-free with devm_spi_alloc_*\n\nWe can't rely on the contents of the devres list during\nspi_unregister_controller(), as the list is already torn down at the\ntime we perform devres_find() for devm_spi_release_controller. This\ncauses devices registered with devm_spi_alloc_{master,slave}() to be\nmistakenly identified as legacy, non-devm managed devices and have their\nreference counters decremented below 0.\n\n------------[ cut here ]------------\nWARNING: CPU: 1 PID: 660 at lib/refcount.c:28 refcount_warn_saturate+0x108/0x174\n[<b0396f04>] (refcount_warn_saturate) from [<b03c56a4>] (kobject_put+0x90/0x98)\n[<b03c5614>] (kobject_put) from [<b0447b4c>] (put_device+0x20/0x24)\n r4:b6700140\n[<b0447b2c>] (put_device) from [<b07515e8>] (devm_spi_release_controller+0x3c/0x40)\n[<b07515ac>] (devm_spi_release_controller) from [<b045343c>] (release_nodes+0x84/0xc4)\n r5:b6700180 r4:b6700100\n[<b04533b8>] (release_nodes) from [<b0454160>] (devres_release_all+0x5c/0x60)\n r8:b1638c54 r7:b117ad94 r6:b1638c10 r5:b117ad94 r4:b163dc10\n[<b0454104>] (devres_release_all) from [<b044e41c>] (__device_release_driver+0x144/0x1ec)\n r5:b117ad94 r4:b163dc10\n[<b044e2d8>] (__device_release_driver) from [<b044f70c>] (device_driver_detach+0x84/0xa0)\n r9:00000000 r8:00000000 r7:b117ad94 r6:b163dc54 r5:b1638c10 r4:b163dc10\n[<b044f688>] (device_driver_detach) from [<b044d274>] (unbind_store+0xe4/0xf8)\n\nInstead, determine the devm allocation state as a flag on the\ncontroller which is guaranteed to be stable during cleanup.",
            "data": {
                "packageName": "linux-libc-dev",
                "packageVersion": "4.19.67-2+deb10u2",
                "imageName": "library/python",
                "imageTag": "3.7.5-buster",
                "imageFilePath": "pygoat/Dockerfile",
                "imageOrigin": "Dockerfile"
            },
            "comments": {
                "comments": ""
            },
            "vulnerabilityDetails": {
                "cvssScore": 0,
                "cveName": "CVE-2021-46959",
                "cweId": "",
                "cvss": null
            }
        },
        {
            "type": "containers",
            "id": "CVE-2021-46959",
            "similarityId": "CVE-2021-46959",
            "status": "RECURRENT",
            "state": "TO_VERIFY",
            "severity": "INFO",
            "confidenceLevel": 0,
            "created": "2024-11-14T03:52:50Z",
            "firstFoundAt": "2024-11-12T12:44:08Z",
            "foundAt": "2024-11-14T03:52:50Z",
            "firstScanId": "ffb57bf8-3538-4457-a5d7-90ffb2ce06bd",
            "description": "In the Linux kernel, the following vulnerability has been resolved:\n\nspi: Fix use-after-free with devm_spi_alloc_*\n\nWe can't rely on the contents of the devres list during\nspi_unregister_controller(), as the list is already torn down at the\ntime we perform devres_find() for devm_spi_release_controller. This\ncauses devices registered with devm_spi_alloc_{master,slave}() to be\nmistakenly identified as legacy, non-devm managed devices and have their\nreference counters decremented below 0.\n\n------------[ cut here ]------------\nWARNING: CPU: 1 PID: 660 at lib/refcount.c:28 refcount_warn_saturate+0x108/0x174\n[<b0396f04>] (refcount_warn_saturate) from [<b03c56a4>] (kobject_put+0x90/0x98)\n[<b03c5614>] (kobject_put) from [<b0447b4c>] (put_device+0x20/0x24)\n r4:b6700140\n[<b0447b2c>] (put_device) from [<b07515e8>] (devm_spi_release_controller+0x3c/0x40)\n[<b07515ac>] (devm_spi_release_controller) from [<b045343c>] (release_nodes+0x84/0xc4)\n r5:b6700180 r4:b6700100\n[<b04533b8>] (release_nodes) from [<b0454160>] (devres_release_all+0x5c/0x60)\n r8:b1638c54 r7:b117ad94 r6:b1638c10 r5:b117ad94 r4:b163dc10\n[<b0454104>] (devres_release_all) from [<b044e41c>] (__device_release_driver+0x144/0x1ec)\n r5:b117ad94 r4:b163dc10\n[<b044e2d8>] (__device_release_driver) from [<b044f70c>] (device_driver_detach+0x84/0xa0)\n r9:00000000 r8:00000000 r7:b117ad94 r6:b163dc54 r5:b1638c10 r4:b163dc10\n[<b044f688>] (device_driver_detach) from [<b044d274>] (unbind_store+0xe4/0xf8)\n\nInstead, determine the devm allocation state as a flag on the\ncontroller which is guaranteed to be stable during cleanup.",
            "data": {
                "packageName": "linux",
                "packageVersion": "4.19.67-2+deb10u2",
                "imageName": "library/python",
                "imageTag": "3.7.5-buster",
                "imageFilePath": "pygoat/Dockerfile",
                "imageOrigin": "Dockerfile"
            },
            "comments": {
                "comments": ""
            },
            "vulnerabilityDetails": {
                "cvssScore": 0,
                "cveName": "CVE-2021-46959",
                "cweId": "",
                "cvss": null
            }
        },
        {
            "type": "containers",
            "id": "CVE-2021-46960",
            "similarityId": "CVE-2021-46960",
            "status": "RECURRENT",
            "state": "TO_VERIFY",
            "severity": "INFO",
            "confidenceLevel": 0,
            "created": "2024-11-14T03:52:50Z",
            "firstFoundAt": "2024-11-12T12:44:08Z",
            "foundAt": "2024-11-14T03:52:50Z",
            "firstScanId": "ffb57bf8-3538-4457-a5d7-90ffb2ce06bd",
            "description": "In the Linux kernel, the following vulnerability has been resolved:\n\ncifs: Return correct error code from smb2_get_enc_key\n\nAvoid a warning if the error percolates back up:\n\n[440700.376476] CIFS VFS: \\\\otters.example.com crypt_message: Could not get encryption key\n[440700.386947] ------------[ cut here ]------------\n[440700.386948] err = 1\n[440700.386977] WARNING: CPU: 11 PID: 2733 at /build/linux-hwe-5.4-p6lk6L/linux-hwe-5.4-5.4.0/lib/errseq.c:74 errseq_set+0x5c/0x70\n...\n[440700.397304] CPU: 11 PID: 2733 Comm: tar Tainted: G           OE     5.4.0-70-generic #78~18.04.1-Ubuntu\n...\n[440700.397334] Call Trace:\n[440700.397346]  __filemap_set_wb_err+0x1a/0x70\n[440700.397419]  cifs_writepages+0x9c7/0xb30 [cifs]\n[440700.397426]  do_writepages+0x4b/0xe0\n[440700.397444]  __filemap_fdatawrite_range+0xcb/0x100\n[440700.397455]  filemap_write_and_wait+0x42/0xa0\n[440700.397486]  cifs_setattr+0x68b/0xf30 [cifs]\n[440700.397493]  notify_change+0x358/0x4a0\n[440700.397500]  utimes_common+0xe9/0x1c0\n[440700.397510]  do_utimes+0xc5/0x150\n[440700.397520]  __x64_sys_utimensat+0x88/0xd0",
            "data": {
                "packageName": "linux",
                "packageVersion": "4.19.67-2+deb10u2",
                "imageName": "library/python",
                "imageTag": "3.7.5-buster",
                "imageFilePath": "pygoat/Dockerfile",
                "imageOrigin": "Dockerfile"
            },
            "comments": {
                "comments": ""
            },
            "vulnerabilityDetails": {
                "cvssScore": 0,
                "cveName": "CVE-2021-46960",
                "cweId": "",
                "cvss": null
            }
        },
        {
            "type": "containers",
            "id": "CVE-2021-46960",
            "similarityId": "CVE-2021-46960",
            "status": "RECURRENT",
            "state": "TO_VERIFY",
            "severity": "INFO",
            "confidenceLevel": 0,
            "created": "2024-11-14T03:52:50Z",
            "firstFoundAt": "2024-11-12T12:44:08Z",
            "foundAt": "2024-11-14T03:52:50Z",
            "firstScanId": "ffb57bf8-3538-4457-a5d7-90ffb2ce06bd",
            "description": "In the Linux kernel, the following vulnerability has been resolved:\n\ncifs: Return correct error code from smb2_get_enc_key\n\nAvoid a warning if the error percolates back up:\n\n[440700.376476] CIFS VFS: \\\\otters.example.com crypt_message: Could not get encryption key\n[440700.386947] ------------[ cut here ]------------\n[440700.386948] err = 1\n[440700.386977] WARNING: CPU: 11 PID: 2733 at /build/linux-hwe-5.4-p6lk6L/linux-hwe-5.4-5.4.0/lib/errseq.c:74 errseq_set+0x5c/0x70\n...\n[440700.397304] CPU: 11 PID: 2733 Comm: tar Tainted: G           OE     5.4.0-70-generic #78~18.04.1-Ubuntu\n...\n[440700.397334] Call Trace:\n[440700.397346]  __filemap_set_wb_err+0x1a/0x70\n[440700.397419]  cifs_writepages+0x9c7/0xb30 [cifs]\n[440700.397426]  do_writepages+0x4b/0xe0\n[440700.397444]  __filemap_fdatawrite_range+0xcb/0x100\n[440700.397455]  filemap_write_and_wait+0x42/0xa0\n[440700.397486]  cifs_setattr+0x68b/0xf30 [cifs]\n[440700.397493]  notify_change+0x358/0x4a0\n[440700.397500]  utimes_common+0xe9/0x1c0\n[440700.397510]  do_utimes+0xc5/0x150\n[440700.397520]  __x64_sys_utimensat+0x88/0xd0",
            "data": {
                "packageName": "linux-libc-dev",
                "packageVersion": "4.19.67-2+deb10u2",
                "imageName": "library/python",
                "imageTag": "3.7.5-buster",
                "imageFilePath": "pygoat/Dockerfile",
                "imageOrigin": "Dockerfile"
            },
            "comments": {
                "comments": ""
            },
            "vulnerabilityDetails": {
                "cvssScore": 0,
                "cveName": "CVE-2021-46960",
                "cweId": "",
                "cvss": null
            }
        },
        {
            "type": "containers",
            "id": "CVE-2021-46963",
            "similarityId": "CVE-2021-46963",
            "status": "RECURRENT",
            "state": "TO_VERIFY",
            "severity": "INFO",
            "confidenceLevel": 0,
            "created": "2024-11-14T03:52:50Z",
            "firstFoundAt": "2024-11-12T12:44:08Z",
            "foundAt": "2024-11-14T03:52:50Z",
            "firstScanId": "ffb57bf8-3538-4457-a5d7-90ffb2ce06bd",
            "description": "In the Linux kernel, the following vulnerability has been resolved:\n\nscsi: qla2xxx: Fix crash in qla2xxx_mqueuecommand()\n\n    RIP: 0010:kmem_cache_free+0xfa/0x1b0\n    Call Trace:\n       qla2xxx_mqueuecommand+0x2b5/0x2c0 [qla2xxx]\n       scsi_queue_rq+0x5e2/0xa40\n       __blk_mq_try_issue_directly+0x128/0x1d0\n       blk_mq_request_issue_directly+0x4e/0xb0\n\nFix incorrect call to free srb in qla2xxx_mqueuecommand(), as srb is now\nallocated by upper layers. This fixes smatch warning of srb unintended\nfree.",
            "data": {
                "packageName": "linux-libc-dev",
                "packageVersion": "4.19.67-2+deb10u2",
                "imageName": "library/python",
                "imageTag": "3.7.5-buster",
                "imageFilePath": "pygoat/Dockerfile",
                "imageOrigin": "Dockerfile"
            },
            "comments": {
                "comments": ""
            },
            "vulnerabilityDetails": {
                "cvssScore": 0,
                "cveName": "CVE-2021-46963",
                "cweId": "",
                "cvss": null
            }
        },
        {
            "type": "containers",
            "id": "CVE-2021-46963",
            "similarityId": "CVE-2021-46963",
            "status": "RECURRENT",
            "state": "TO_VERIFY",
            "severity": "INFO",
            "confidenceLevel": 0,
            "created": "2024-11-14T03:52:50Z",
            "firstFoundAt": "2024-11-12T12:44:08Z",
            "foundAt": "2024-11-14T03:52:50Z",
            "firstScanId": "ffb57bf8-3538-4457-a5d7-90ffb2ce06bd",
            "description": "In the Linux kernel, the following vulnerability has been resolved:\n\nscsi: qla2xxx: Fix crash in qla2xxx_mqueuecommand()\n\n    RIP: 0010:kmem_cache_free+0xfa/0x1b0\n    Call Trace:\n       qla2xxx_mqueuecommand+0x2b5/0x2c0 [qla2xxx]\n       scsi_queue_rq+0x5e2/0xa40\n       __blk_mq_try_issue_directly+0x128/0x1d0\n       blk_mq_request_issue_directly+0x4e/0xb0\n\nFix incorrect call to free srb in qla2xxx_mqueuecommand(), as srb is now\nallocated by upper layers. This fixes smatch warning of srb unintended\nfree.",
            "data": {
                "packageName": "linux",
                "packageVersion": "4.19.67-2+deb10u2",
                "imageName": "library/python",
                "imageTag": "3.7.5-buster",
                "imageFilePath": "pygoat/Dockerfile",
                "imageOrigin": "Dockerfile"
            },
            "comments": {
                "comments": ""
            },
            "vulnerabilityDetails": {
                "cvssScore": 0,
                "cveName": "CVE-2021-46963",
                "cweId": "",
                "cvss": null
            }
        }
    ],
    "totalCount": 6714
}